2020-07-25 01:11:25,062 INFO: Application started [in /home/om/PycharmProjects/code-quality/step_3/application-name/app/__init__.py:30]
2020-07-25 01:11:31,630 ERROR: Error occurred while getting all user names [in /home/om/PycharmProjects/code-quality/step_3/application-name/app/dao/user_dao.py:22]
Traceback (most recent call last):
  File "/home/om/anaconda3/envs/code-quality/lib/python3.7/site-packages/sqlalchemy/engine/base.py", line 1278, in _execute_context
    cursor, statement, parameters, context
  File "/home/om/anaconda3/envs/code-quality/lib/python3.7/site-packages/sqlalchemy/engine/default.py", line 593, in do_execute
    cursor.execute(statement, parameters)
sqlite3.OperationalError: no such table: user

The above exception was the direct cause of the following exception:

Traceback (most recent call last):
  File "/home/om/PycharmProjects/code-quality/step_3/application-name/app/dao/user_dao.py", line 19, in get_all_users_name
    user_names = db.session.query(distinct(Users.name)).filter(Users.name == name).all()
  File "/home/om/anaconda3/envs/code-quality/lib/python3.7/site-packages/sqlalchemy/orm/query.py", line 3341, in all
    return list(self)
  File "/home/om/anaconda3/envs/code-quality/lib/python3.7/site-packages/sqlalchemy/orm/query.py", line 3503, in __iter__
    return self._execute_and_instances(context)
  File "/home/om/anaconda3/envs/code-quality/lib/python3.7/site-packages/sqlalchemy/orm/query.py", line 3528, in _execute_and_instances
    result = conn.execute(querycontext.statement, self._params)
  File "/home/om/anaconda3/envs/code-quality/lib/python3.7/site-packages/sqlalchemy/engine/base.py", line 1014, in execute
    return meth(self, multiparams, params)
  File "/home/om/anaconda3/envs/code-quality/lib/python3.7/site-packages/sqlalchemy/sql/elements.py", line 298, in _execute_on_connection
    return connection._execute_clauseelement(self, multiparams, params)
  File "/home/om/anaconda3/envs/code-quality/lib/python3.7/site-packages/sqlalchemy/engine/base.py", line 1133, in _execute_clauseelement
    distilled_params,
  File "/home/om/anaconda3/envs/code-quality/lib/python3.7/site-packages/sqlalchemy/engine/base.py", line 1318, in _execute_context
    e, statement, parameters, cursor, context
  File "/home/om/anaconda3/envs/code-quality/lib/python3.7/site-packages/sqlalchemy/engine/base.py", line 1512, in _handle_dbapi_exception
    sqlalchemy_exception, with_traceback=exc_info[2], from_=e
  File "/home/om/anaconda3/envs/code-quality/lib/python3.7/site-packages/sqlalchemy/util/compat.py", line 178, in raise_
    raise exception
  File "/home/om/anaconda3/envs/code-quality/lib/python3.7/site-packages/sqlalchemy/engine/base.py", line 1278, in _execute_context
    cursor, statement, parameters, context
  File "/home/om/anaconda3/envs/code-quality/lib/python3.7/site-packages/sqlalchemy/engine/default.py", line 593, in do_execute
    cursor.execute(statement, parameters)
sqlalchemy.exc.OperationalError: (sqlite3.OperationalError) no such table: user
[SQL: SELECT DISTINCT user.name AS anon_1 
FROM user 
WHERE user.name = ?]
[parameters: ('shubh',)]
(Background on this error at: http://sqlalche.me/e/13/e3q8)
2020-07-25 01:11:31,634 ERROR: Exception on /index/shubh [GET] [in /home/om/anaconda3/envs/code-quality/lib/python3.7/site-packages/flask/app.py:1892]
Traceback (most recent call last):
  File "/home/om/anaconda3/envs/code-quality/lib/python3.7/site-packages/flask/app.py", line 2447, in wsgi_app
    response = self.full_dispatch_request()
  File "/home/om/anaconda3/envs/code-quality/lib/python3.7/site-packages/flask/app.py", line 1952, in full_dispatch_request
    rv = self.handle_user_exception(e)
  File "/home/om/anaconda3/envs/code-quality/lib/python3.7/site-packages/flask_cors/extension.py", line 161, in wrapped_function
    return cors_after_request(app.make_response(f(*args, **kwargs)))
  File "/home/om/anaconda3/envs/code-quality/lib/python3.7/site-packages/flask/app.py", line 1821, in handle_user_exception
    reraise(exc_type, exc_value, tb)
  File "/home/om/anaconda3/envs/code-quality/lib/python3.7/site-packages/flask/_compat.py", line 39, in reraise
    raise value
  File "/home/om/anaconda3/envs/code-quality/lib/python3.7/site-packages/flask/app.py", line 1950, in full_dispatch_request
    rv = self.dispatch_request()
  File "/home/om/anaconda3/envs/code-quality/lib/python3.7/site-packages/flask/app.py", line 1936, in dispatch_request
    return self.view_functions[rule.endpoint](**req.view_args)
  File "/home/om/PycharmProjects/code-quality/step_3/application-name/app/routes.py", line 8, in index
    users = data_service.get_user_information(name)
  File "/home/om/PycharmProjects/code-quality/step_3/application-name/app/services/data_service.py", line 6, in get_user_information
    for user in users:
TypeError: 'bool' object is not iterable
